Failed to create password reset token for ibehemmanuel32@gmail.com: no such table: django_rest_passwordreset_resetpasswordtoken
Internal Server Error: /account/password_reset/request/
Failed to create password reset token for ibehemmanuel32@gmail.com: no such table: django_rest_passwordreset_resetpasswordtoken
Internal Server Error: /account/password_reset/
Failed to create password reset token for ibehemmanuel32@gmail.com: no such table: django_rest_passwordreset_resetpasswordtoken
Internal Server Error: /account/password_reset/
Failed to create password reset token for ibehemmanuel32@gmail.com: no such table: django_rest_passwordreset_resetpasswordtoken
Internal Server Error: /account/password_reset/
Failed to create password reset token for ibehemmanuel32@gmail.com: no such table: django_rest_passwordreset_resetpasswordtoken
Internal Server Error: /account/password_reset/
Failed to create password reset token for ibehemmanuel32@gmail.com: no such table: django_rest_passwordreset_resetpasswordtoken
Internal Server Error: /account/password_reset/
Failed to create password reset token for ibehemmanuel32@gmail.com: no such table: django_rest_passwordreset_resetpasswordtoken
Internal Server Error: /account/password_reset/
Failed to create password reset token for ibehemmanuel32@gmail.com: no such table: django_rest_passwordreset_resetpasswordtoken
Internal Server Error: /account/password_reset/
Failed to create password reset token for ibehemmanuel32@gmail.com: name 'reset_password_token_created' is not defined
Internal Server Error: /account/password_reset/
Internal Server Error: /account/verify_code/
Traceback (most recent call last):
  File "C:\Users\LENOVO\OneDrive\Desktop\backendbit\env\Lib\site-packages\django\core\handlers\exception.py", line 55, in inner
    response = get_response(request)
  File "C:\Users\LENOVO\OneDrive\Desktop\backendbit\env\Lib\site-packages\django\core\handlers\base.py", line 197, in _get_response
    response = wrapped_callback(request, *callback_args, **callback_kwargs)
  File "C:\Users\LENOVO\OneDrive\Desktop\backendbit\env\Lib\site-packages\django\views\decorators\csrf.py", line 65, in _view_wrapper
    return view_func(request, *args, **kwargs)
  File "C:\Users\LENOVO\OneDrive\Desktop\backendbit\env\Lib\site-packages\django\views\generic\base.py", line 104, in view
    return self.dispatch(request, *args, **kwargs)
           ~~~~~~~~~~~~~^^^^^^^^^^^^^^^^^^^^^^^^^^
  File "C:\Users\LENOVO\OneDrive\Desktop\backendbit\env\Lib\site-packages\rest_framework\views.py", line 515, in dispatch
    response = self.handle_exception(exc)
  File "C:\Users\LENOVO\OneDrive\Desktop\backendbit\env\Lib\site-packages\rest_framework\views.py", line 475, in handle_exception
    self.raise_uncaught_exception(exc)
    ~~~~~~~~~~~~~~~~~~~~~~~~~~~~~^^^^^
  File "C:\Users\LENOVO\OneDrive\Desktop\backendbit\env\Lib\site-packages\rest_framework\views.py", line 486, in raise_uncaught_exception
    raise exc
  File "C:\Users\LENOVO\OneDrive\Desktop\backendbit\env\Lib\site-packages\rest_framework\views.py", line 512, in dispatch
    response = handler(request, *args, **kwargs)
  File "C:\Users\LENOVO\OneDrive\Desktop\backendbit\env\Lib\site-packages\rest_framework\decorators.py", line 50, in handler
    return func(*args, **kwargs)
  File "C:\Users\LENOVO\OneDrive\Desktop\backendbit\bitphyte\account\views.py", line 86, in code_verification
    user.save()
    ~~~~~~~~~^^
  File "C:\Users\LENOVO\OneDrive\Desktop\backendbit\bitphyte\account\models.py", line 80, in save
    super(User, self).save(*args, **kwargs)
    ~~~~~~~~~~~~~~~~~~~~~~^^^^^^^^^^^^^^^^^
  File "C:\Users\LENOVO\OneDrive\Desktop\backendbit\env\Lib\site-packages\django\contrib\auth\base_user.py", line 65, in save
    super().save(*args, **kwargs)
    ~~~~~~~~~~~~^^^^^^^^^^^^^^^^^
  File "C:\Users\LENOVO\OneDrive\Desktop\backendbit\env\Lib\site-packages\django\db\models\base.py", line 902, in save
    self.save_base(
    ~~~~~~~~~~~~~~^
        using=using,
        ^^^^^^^^^^^^
    ...<2 lines>...
        update_fields=update_fields,
        ^^^^^^^^^^^^^^^^^^^^^^^^^^^^
    )
    ^
  File "C:\Users\LENOVO\OneDrive\Desktop\backendbit\env\Lib\site-packages\django\db\models\base.py", line 1023, in save_base
    post_save.send(
    ~~~~~~~~~~~~~~^
        sender=origin,
        ^^^^^^^^^^^^^^
    ...<4 lines>...
        using=using,
        ^^^^^^^^^^^^
    )
    ^
  File "C:\Users\LENOVO\OneDrive\Desktop\backendbit\env\Lib\site-packages\django\dispatch\dispatcher.py", line 189, in send
    response = receiver(signal=self, sender=sender, **named)
  File "C:\Users\LENOVO\OneDrive\Desktop\backendbit\bitphyte\account\signals.py", line 70, in send_welcome_email
    text_content = render_to_string('email/welcome_email.txt', context)
  File "C:\Users\LENOVO\OneDrive\Desktop\backendbit\env\Lib\site-packages\django\template\loader.py", line 61, in render_to_string
    template = get_template(template_name, using=using)
  File "C:\Users\LENOVO\OneDrive\Desktop\backendbit\env\Lib\site-packages\django\template\loader.py", line 19, in get_template
    raise TemplateDoesNotExist(template_name, chain=chain)
django.template.exceptions.TemplateDoesNotExist: email/welcome_email.txt
Internal Server Error: /management/referral-details/
Traceback (most recent call last):
  File "C:\Users\LENOVO\OneDrive\Desktop\backendbit\env\Lib\site-packages\django\core\handlers\exception.py", line 55, in inner
    response = get_response(request)
  File "C:\Users\LENOVO\OneDrive\Desktop\backendbit\env\Lib\site-packages\django\core\handlers\base.py", line 197, in _get_response
    response = wrapped_callback(request, *callback_args, **callback_kwargs)
  File "C:\Users\LENOVO\OneDrive\Desktop\backendbit\env\Lib\site-packages\django\views\decorators\csrf.py", line 65, in _view_wrapper
    return view_func(request, *args, **kwargs)
  File "C:\Users\LENOVO\OneDrive\Desktop\backendbit\env\Lib\site-packages\django\views\generic\base.py", line 104, in view
    return self.dispatch(request, *args, **kwargs)
           ~~~~~~~~~~~~~^^^^^^^^^^^^^^^^^^^^^^^^^^
  File "C:\Users\LENOVO\OneDrive\Desktop\backendbit\env\Lib\site-packages\rest_framework\views.py", line 515, in dispatch
    response = self.handle_exception(exc)
  File "C:\Users\LENOVO\OneDrive\Desktop\backendbit\env\Lib\site-packages\rest_framework\views.py", line 475, in handle_exception
    self.raise_uncaught_exception(exc)
    ~~~~~~~~~~~~~~~~~~~~~~~~~~~~~^^^^^
  File "C:\Users\LENOVO\OneDrive\Desktop\backendbit\env\Lib\site-packages\rest_framework\views.py", line 486, in raise_uncaught_exception
    raise exc
  File "C:\Users\LENOVO\OneDrive\Desktop\backendbit\env\Lib\site-packages\rest_framework\views.py", line 512, in dispatch
    response = handler(request, *args, **kwargs)
  File "C:\Users\LENOVO\OneDrive\Desktop\backendbit\env\Lib\site-packages\rest_framework\decorators.py", line 50, in handler
    return func(*args, **kwargs)
  File "C:\Users\LENOVO\OneDrive\Desktop\backendbit\bitphyte\management\views.py", line 33, in get_referral_details
    return Response(serializer.data, status=status.HTTP_200_OK)
                    ^^^^^^^^^^^^^^^
  File "C:\Users\LENOVO\OneDrive\Desktop\backendbit\env\Lib\site-packages\rest_framework\serializers.py", line 797, in data
    ret = super().data
          ^^^^^^^^^^^^
  File "C:\Users\LENOVO\OneDrive\Desktop\backendbit\env\Lib\site-packages\rest_framework\serializers.py", line 251, in data
    self._data = self.to_representation(self.instance)
                 ~~~~~~~~~~~~~~~~~~~~~~^^^^^^^^^^^^^^^
  File "C:\Users\LENOVO\OneDrive\Desktop\backendbit\env\Lib\site-packages\rest_framework\serializers.py", line 716, in to_representation
    self.child.to_representation(item) for item in iterable
    ~~~~~~~~~~~~~~~~~~~~~~~~~~~~^^^^^^
  File "C:\Users\LENOVO\OneDrive\Desktop\backendbit\env\Lib\site-packages\rest_framework\serializers.py", line 525, in to_representation
    for field in fields:
                 ^^^^^^
  File "C:\Users\LENOVO\OneDrive\Desktop\backendbit\env\Lib\site-packages\rest_framework\serializers.py", line 386, in _readable_fields
    for field in self.fields.values():
                 ^^^^^^^^^^^
  File "C:\Users\LENOVO\OneDrive\Desktop\backendbit\env\Lib\site-packages\django\utils\functional.py", line 47, in __get__
    res = instance.__dict__[self.name] = self.func(instance)
                                         ~~~~~~~~~^^^^^^^^^^
  File "C:\Users\LENOVO\OneDrive\Desktop\backendbit\env\Lib\site-packages\rest_framework\serializers.py", line 374, in fields
    for key, value in self.get_fields().items():
                      ~~~~~~~~~~~~~~~^^
  File "C:\Users\LENOVO\OneDrive\Desktop\backendbit\env\Lib\site-packages\rest_framework\serializers.py", line 1081, in get_fields
    field_names = self.get_field_names(declared_fields, info)
  File "C:\Users\LENOVO\OneDrive\Desktop\backendbit\env\Lib\site-packages\rest_framework\serializers.py", line 1177, in get_field_names
    assert field_name in fields, (
           ^^^^^^^^^^^^^^^^^^^^
AssertionError: The field 'referee_details' was declared on serializer ReferralSerializer, but has not been included in the 'fields' option.
